<?xml version="1.0"?>
<robot name="quadruped_arm_robot">
  
  
 
  
  <link name="base_link">
    <inertial>
      <origin xyz="0  0 0"/>
      <mass value="0.400"/>
      <inertia ixx="0.0003" iyy="0.0003" izz="0.0003" ixy="0" ixz="0" iyz="0"/>
    </inertial>
    <visual>
    <origin xyz="0 0 0" rpy="0 0 0"/>
    <geometry>
      <mesh
        filename="/home/edipo/ros2_orange/src/quadruped_arm_motion/meshes/Body.stl"
        scale="1 1 1"/>
    </geometry>
    </visual>
    <collision>
      <origin xyz="0 0 0" rpy="0 0 0"/>
      <geometry>
        <mesh
          filename="/home/edipo/ros2_orange/src/quadruped_arm_motion/meshes/Body.stl"
          scale="1 1 1"/>
      </geometry>
      <surface>
        <friction>
          <ode>
            <mu>1.0</mu>
            <mu2>1.0</mu2>
          </ode>
        </friction>
        <contact>
          <ode>
            <kp>10</kp>
            <kd>50</kd>
          </ode>
        </contact>
      </surface>
    </collision>
  </link>
  
  <link name="frontLeft_hip_motor">
    <inertial><mass value="0.158"/><origin xyz="0 0 0"/>
      <inertia ixx="0.00016" iyy="0.00016" izz="0.00016" ixy="0" ixz="0" iyz="0"/></inertial>

    <inertial><mass value="0.158"/><origin xyz="0 0 0"/>
      <inertia ixx="0.00016" iyy="0.00016" izz="0.00016" ixy="0" ixz="0" iyz="0"/></inertial>
    <visual>
    <origin xyz="0.03 0.019 -0.08" rpy="0 0 0"/>
    <geometry>
      <mesh
        filename="/home/edipo/ros2_orange/src/quadruped_arm_motion/meshes/servo_8y.stl"
        scale="1 1 1"/>
    </geometry>
    </visual>
    <collision>
      <origin xyz="0.03 0.019 -0.08" rpy="0 0 0"/>
      <geometry>
        <mesh
          filename="/home/edipo/ros2_orange/src/quadruped_arm_motion/meshes/servo_8y.stl"
          scale="1 1 1"/>
      </geometry>
      <surface>
        <friction>
          <ode>
            <mu>1.0</mu>
            <mu2>1.0</mu2>
          </ode>
        </friction>
        <contact>
          <ode>
            <kp>10</kp>
            <kd>50</kd>
          </ode>
        </contact>
      </surface>
    </collision>
  </link>
  <joint name="frontLeft_hip_motor_joint" type="revolute">
    <parent link="base_link"/>
    <child  link="frontLeft_hip_motor"/>
    <origin xyz="0.235 0.03 0.03" rpy="0 1.5708 0"/>
    <axis xyz="0 0 1"/>
    <limit lower="-3.14" upper="3.14" effort="50.88" velocity="1"/>
    <dynamics damping="0.05" friction="2.5"/>
    <safety>
    <soft_lower_limit>-3.0</soft_lower_limit>
    <soft_upper_limit> 3.0</soft_upper_limit>
    <k_position> 50.0 </k_position>
    <k_velocity> 10.0  </k_velocity>
    </safety>
  </joint>

  <link name="frontLeft_knee">
    <inertial><mass value="0.158"/><origin xyz="0 0 0"/>
    <inertia ixx="0.00016" iyy="0.00016" izz="0.00016" ixy="0" ixz="0" iyz="0"/></inertial>
    <visual   ><geometry><cylinder radius="0.015" length="0.05"/></geometry></visual>
    <collision><geometry><cylinder radius="0.015" length="0.05"/></geometry>
    <surface><friction><ode><mu>1.0</mu><mu2>1.0</mu2></ode></friction><contact>
    <ode><kp>10</kp><kd>50</kd></ode></contact></surface>
    </collision>
  </link>
  <joint name="frontLeft_knee_joint" type="revolute">
    <parent link="frontLeft_hip_motor"/>
    <child  link="frontLeft_knee"/>
    <origin xyz="0.035 0.055 -0.025" rpy="1.5708 0 0"/>
    <axis xyz="0 0 1"/>
    <limit lower="-1.57" upper="1.57" effort="50.88" velocity="1"/>
    <dynamics damping="0.05" friction="2.5"/>
    <safety>
    <soft_lower_limit>-3.0</soft_lower_limit>
    <soft_upper_limit> 3.0</soft_upper_limit>
    <k_position> 50.0 </k_position>
    <k_velocity> 10.0  </k_velocity>
    </safety>
  </joint>
  <link name="frontLeft_connector">
    <inertial><mass value="0.05"/><origin xyz="0 0 0"/>
      <inertia ixx="0.00016" iyy="0.00016" izz="0.00016" ixy="0" ixz="0" iyz="0"/></inertial>
    <visual   ><geometry><box size="0.125 0.04 0.02" /></geometry></visual>
    <collision><geometry><box size="0.125 0.04 0.02" /></geometry>
    <surface><friction><ode><mu>1.0</mu><mu2>1.0</mu2></ode></friction><contact><ode><kp>10</kp><kd>50</kd></ode></contact></surface>
    </collision>
  </link>
  <joint name="frontLeft_connectorJoin" type="fixed">
    <parent link="frontLeft_knee"/>
    <child  link="frontLeft_connector"/>
    <origin xyz="0.08 0 0" rpy="0 0 0" />
    <axis xyz="0 0 1"/>
    <dynamics damping="0.05" friction="2.5"/>
    <safety>
    <soft_lower_limit>-3.0</soft_lower_limit>
    <soft_upper_limit> 3.0</soft_upper_limit>
    <param name="pos_kp">10</param>
    <param name="pos_ki">1</param>
    <param name="pos_kd">2</param>
    <param name="pos_max_integral_error">10000</param>
    <param name="vel_kp">10</param>
    <param name="vel_ki">5</param>
    <param name="vel_kd">2</param>
    <param name="vel_max_integral_error">10000</param>
    </safety>
  </joint> 

  <link name="frontLeft_ankle">
    <inertial><mass value="0.158"/><origin xyz="0 0 0"/>
    <inertia ixx="0.00016" iyy="0.00016" izz="0.00016" ixy="0" ixz="0" iyz="0"/></inertial>
    <visual   ><geometry><cylinder radius="0.015" length="0.05"/></geometry></visual>
     <collision><geometry><cylinder radius="0.015" length="0.05"/></geometry>
    <surface><friction><ode><mu>1.0</mu><mu2>1.0</mu2></ode>
    </friction><contact><ode><kp>10</kp><kd>50</kd></ode></contact></surface>
    </collision>
  </link>
  <joint name="frontLeft_ankle_joint" type="revolute">
    <parent link="frontLeft_connector"/>
    <child  link="frontLeft_ankle"/>
    <origin xyz="0.08 0 0" rpy="0.1 0 0.8"/>
    <axis xyz="0 0 1"/>
    <limit lower="-3.14" upper="3.14" effort="50.88" velocity="1"/>
    <dynamics damping="0.05" friction="2.5"/>
    <safety>
    <soft_lower_limit>-3.0</soft_lower_limit>
    <soft_upper_limit> 3.0</soft_upper_limit>
    <k_position> 50.0 </k_position>
    <k_velocity> 10.0  </k_velocity>
    </safety>
  </joint>

  <link name="frontLeft_foot">
    <inertial><mass value="0.03"/><origin xyz="0 0 0"/>
    <inertia ixx="2e-5" iyy="2e-5" izz="2e-5" ixy="0" ixz="0" iyz="0"/></inertial>
    <visual>
    <origin xyz="0 0 0" rpy="0 0 0"/>
    <geometry>
      <mesh
        filename="/home/edipo/ros2_orange/src/quadruped_arm_motion/meshes/foot_3.stl"
        scale="1 1 1"/>
    </geometry>
    </visual>
    <collision>
    <origin xyz="0 0 0" rpy="0 0 0"/>
    <geometry>
      <mesh
        filename="/home/edipo/ros2_orange/src/quadruped_arm_motion/meshes/foot_3.stl"
        scale="1 1 1"/>
    </geometry>
    <surface>
      <friction>
        <ode>
          <mu>1.0</mu>
          <mu2>1.0</mu2>
        </ode>
      </friction>
      <contact>
        <ode>
          <kp>10</kp>
          <kd>50</kd>
        </ode>
      </contact>
    </surface>
    </collision>
  </link>
  <joint name="frontLeft_foot_joint" type="fixed">
    <parent link="frontLeft_ankle"/>
    <child  link="frontLeft_foot"/>
    <origin xyz="0.06 0 0"/>
    <dynamics damping="0.05" friction="2.5"/>
     
    <safety>
    <soft_lower_limit>-3.0</soft_lower_limit>
    <soft_upper_limit> 3.0</soft_upper_limit>
    <k_position> 50.0 </k_position>
    <k_velocity> 10.0  </k_velocity>
    </safety>
  </joint>
 
  <link name="frontRight_hip_motor">
    <inertial><mass value="0.158"/><origin xyz="0 0 0"/>
      <inertia ixx="0.00016" iyy="0.00016" izz="0.00016" ixy="0" ixz="0" iyz="0"/></inertial>
    <visual>
    <origin xyz="0.03 0.005 -0.08" rpy="0 0 0"/>
    <geometry>
      <mesh
        filename="/home/edipo/ros2_orange/src/quadruped_arm_motion/meshes/servo_7y.stl"
        scale="1 1 1"/>
    </geometry>
    </visual>
    <collision>
      <origin xyz="0.03 -0.005 -0.08" rpy="0 0 0"/>
      <geometry>
        <mesh
          filename="/home/edipo/ros2_orange/src/quadruped_arm_motion/meshes/servo_7y.stl"
          scale="1 1 1"/>
      </geometry>
      <surface>
        <friction>
          <ode>
            <mu>1.0</mu>
            <mu2>1.0</mu2>
          </ode>
        </friction>
        <contact>
          <ode>
            <kp>10</kp>
            <kd>50</kd>
          </ode>
        </contact>
      </surface>
    </collision>
  </link>
  <joint name="frontRight_hip_motor_joint" type="revolute">
    <parent link="base_link"/>
    <child  link="frontRight_hip_motor"/>
    <origin xyz="0.235 -0.085 0.03" rpy="0 1.5708 0"/>
    <axis xyz="0 0 1"/>
    <limit lower="-3.14" upper="3.14" effort="50.88" velocity="1"/>
    <dynamics damping="0.05" friction="2.5"/>
    <safety>
    <soft_lower_limit>-3.0</soft_lower_limit>
    <soft_upper_limit> 3.0</soft_upper_limit>
    <k_position> 50.0 </k_position>
    <k_velocity> 10.0  </k_velocity>
    </safety>
  </joint>

  <link name="frontRight_knee">
    <inertial><mass value="0.158"/><origin xyz="0 0 0"/>
      <inertia ixx="0.00016" iyy="0.00016" izz="0.00016" ixy="0" ixz="0" iyz="0"/></inertial>
    <visual   ><geometry><cylinder radius="0.015" length="0.05"/></geometry></visual>
    <collision><geometry><cylinder radius="0.015" length="0.05"/></geometry>
    <surface><friction><ode><mu>1.0</mu><mu2>1.0</mu2></ode></friction><contact><ode><kp>10</kp><kd>50</kd></ode></contact></surface>
    </collision>
  </link>
  <joint name="frontRight_knee_joint" type="revolute">
    <parent link="frontRight_hip_motor"/>
    <child  link="frontRight_knee"/>
    <origin xyz="0.035 -0.055 -0.025" rpy="1.5708 0 0"/>
    <axis xyz="0 0 1"/>
    <limit lower="-1.57" upper="1.57" effort="50.88" velocity="1"/>
    <dynamics damping="0.05" friction="2.5"/>
    <safety>
    <soft_lower_limit>-3.0</soft_lower_limit>
    <soft_upper_limit> 3.0</soft_upper_limit>
    <k_position> 50.0 </k_position>
    <k_velocity> 10.0  </k_velocity>
    </safety>
  </joint>

  <link name="frontRight_connector">
    <inertial><mass value="0.05"/><origin xyz="0 0 0"/>
      <inertia ixx="0.00016" iyy="0.00016" izz="0.00016" ixy="0" ixz="0" iyz="0"/></inertial>
    <visual   ><geometry><box size="0.125 0.04 0.02" /></geometry></visual>
    <collision><geometry><box size="0.125 0.04 0.02" /></geometry>
    <surface><friction><ode><mu>1.0</mu><mu2>1.0</mu2></ode></friction><contact><ode><kp>10</kp><kd>50</kd></ode></contact></surface>
    </collision>
  </link>
  <joint name="frontRight_connectorJoin" type="fixed">
    <parent link="frontRight_knee"/>
    <child  link="frontRight_connector"/>
    <origin xyz="0.08 0 0" rpy="0 0 0" />
    <axis xyz="0 0 1"/>
    <dynamics damping="0.05" friction="2.5"/>
    <safety>
    <soft_lower_limit>-3.0</soft_lower_limit>
    <soft_upper_limit> 3.0</soft_upper_limit>
    <param name="pos_kp">10</param>
    <param name="pos_ki">1</param>
    <param name="pos_kd">2</param>
    <param name="pos_max_integral_error">10000</param>
    <param name="vel_kp">10</param>
    <param name="vel_ki">5</param>
    <param name="vel_kd">2</param>
    <param name="vel_max_integral_error">10000</param>
    </safety>
  </joint> 


  <link name="frontRight_ankle">
    <inertial><mass value="0.158"/><origin xyz="0 0 0"/>
    <inertia ixx="0.00016" iyy="0.00016" izz="0.00016" ixy="0" ixz="0" iyz="0"/></inertial>
    <visual   ><geometry><cylinder radius="0.015" length="0.05"/></geometry></visual>
     <collision><geometry><cylinder radius="0.015" length="0.05"/></geometry>
    <surface><friction><ode><mu>1.0</mu><mu2>1.0</mu2></ode>
    </friction><contact><ode><kp>10</kp><kd>50</kd></ode></contact></surface>
    </collision>
  </link>
  <joint name="frontRight_ankle_joint" type="revolute">
    <parent link="frontRight_connector"/>
    <child  link="frontRight_ankle"/>
    <origin xyz="0.08 0 0" rpy="0.1 0 0.8"/>
    <axis xyz="0 0 1"/>
    <limit lower="-3.14" upper="3.14" effort="50.88" velocity="1"/>
    <dynamics damping="0.05" friction="2.5"/>
    <safety>
    <soft_lower_limit>-3.0</soft_lower_limit>
    <soft_upper_limit> 3.0</soft_upper_limit>
    <k_position> 50.0 </k_position>
    <k_velocity> 10.0  </k_velocity>
    </safety>
  </joint>

  <link name="frontRight_foot">
    <inertial><mass value="0.03"/><origin xyz="0 0 0"/>
      <inertia ixx="2e-5" iyy="2e-5" izz="2e-5" ixy="0" ixz="0" iyz="0"/></inertial>
    <visual>
    <origin xyz="0 0 0" rpy="0 0 0"/>
    <geometry>
      <mesh
        filename="/home/edipo/ros2_orange/src/quadruped_arm_motion/meshes/foot_3.stl"
        scale="1 1 1"/>
    </geometry>
    </visual>
    <collision>
    <origin xyz="0 0 0" rpy="0 0 0"/>
    <geometry>
      <mesh
        filename="/home/edipo/ros2_orange/src/quadruped_arm_motion/meshes/foot_3.stl"
        scale="1 1 1"/>
    </geometry>
    <surface>
      <friction>
        <ode>
          <mu>1.0</mu>
          <mu2>1.0</mu2>
        </ode>
      </friction>
      <contact>
        <ode>
          <kp>10</kp>
          <kd>50</kd>
        </ode>
      </contact>
    </surface>
    </collision>
  </link>
  <joint name="frontRight_foot_joint" type="fixed">
    <parent link="frontRight_ankle"/>
    <child  link="frontRight_foot"/>
    <origin xyz="0.06 0 0"/>
     
    <dynamics damping="0.05" friction="2.5"/>
    <safety>
    <soft_lower_limit>-3.0</soft_lower_limit>
    <soft_upper_limit> 3.0</soft_upper_limit>
    <k_position> 50.0 </k_position>
    <k_velocity> 10.0  </k_velocity>
    </safety>
  </joint>
  
  <link name="backLeft_hip_motor">
    <inertial><mass value="0.158"/><origin xyz="0 0 0"/>
    <inertia ixx="0.00016" iyy="0.00016" izz="0.00016" ixy="0" ixz="0" iyz="0"/></inertial>
    <visual>
    <origin xyz="0.035 0.035 -0.05" rpy="0 0 0"/> <!-- Altuura dentro -lado -->
    <geometry>
      <mesh
        filename="/home/edipo/ros2_orange/src/quadruped_arm_motion/meshes/servo_8y.stl"
        scale="1 1 1"/>
    </geometry>
    </visual>
    <collision>
      <origin xyz="0.035 0.035 -0.05" rpy="0 0 0"/>
      <geometry>
        <mesh
          filename="/home/edipo/ros2_orange/src/quadruped_arm_motion/meshes/servo_8y.stl"
          scale="1 1 1"/>
      </geometry>
      <surface>
        <friction>
          <ode>
            <mu>1.0</mu>
            <mu2>1.0</mu2>
          </ode>
        </friction>
        <contact>
          <ode>
            <kp>10</kp>
            <kd>50</kd>
          </ode>
        </contact>
      </surface>
    </collision>
  </link>
  <joint name="backLeft_hip_motor_joint" type="revolute">
    <parent link="base_link"/>
    <child  link="backLeft_hip_motor"/>
    <origin xyz="-0.275 0.03 0.03" rpy="0 1.5708 0"/>
    <axis xyz="0 0 1"/>
    <limit lower="-3.14" upper="3.14" effort="50.88" velocity="1"/>
    <dynamics damping="0.05" friction="2.5"/>
    <safety>
    <soft_lower_limit>-3.0</soft_lower_limit>
    <soft_upper_limit> 3.0</soft_upper_limit>
    <k_position> 50.0 </k_position>
    <k_velocity> 10.0  </k_velocity>
    </safety>
  </joint>

  <link name="backLeft_knee">
    <inertial><mass value="0.158"/><origin xyz="0 0 0"/>
      <inertia ixx="0.00016" iyy="0.00016" izz="0.00016" ixy="0" ixz="0" iyz="0"/></inertial>
    <visual   ><geometry><cylinder radius="0.015" length="0.05"/></geometry></visual>
    <collision><geometry><cylinder radius="0.015" length="0.05"/></geometry>
    <surface><friction><ode><mu>1.0</mu><mu2>1.0</mu2></ode></friction><contact><ode><kp>10</kp><kd>50</kd></ode></contact></surface>
    </collision>
  </link>
  <joint name="backLeft_knee_joint" type="revolute">
    <parent link="backLeft_hip_motor"/>
    <child  link="backLeft_knee"/>
    <origin xyz="0.035 0.055 0.025" rpy="1.5708 0.5 0"/>
    <axis xyz="0 0 1"/>
    <limit lower="-1.57" upper="1.57" effort="50.88" velocity="1"/>
    <dynamics damping="0.05" friction="2.5"/>
    <safety>
    <soft_lower_limit>-3.0</soft_lower_limit>
    <soft_upper_limit> 3.0</soft_upper_limit>
    <k_position> 50.0 </k_position>
    <k_velocity> 10.0  </k_velocity>
    </safety>
  </joint>

  <link name="backLeft_connector">
    <inertial><mass value="0.05"/><origin xyz="0 0 0"/>
      <inertia ixx="0.00016" iyy="0.00016" izz="0.00016" ixy="0" ixz="0" iyz="0"/></inertial>
    <visual   ><geometry><box size="0.125 0.04 0.02" /></geometry></visual>
    <collision><geometry><box size="0.125 0.04 0.02" /></geometry>
    <surface><friction><ode><mu>1.0</mu><mu2>1.0</mu2></ode></friction><contact><ode><kp>10</kp><kd>50</kd></ode></contact></surface>
    </collision>
  </link>
  <joint name="backLeft_connectorJoin" type="fixed">
    <parent link="backLeft_knee"/>
    <child  link="backLeft_connector"/>
    <origin xyz="0.08 0 0" rpy="0 0 0" />
    <axis xyz="0 0 1"/>
    <dynamics damping="0.05" friction="2.5"/>
    <safety>
    <soft_lower_limit>-3.0</soft_lower_limit>
    <soft_upper_limit> 3.0</soft_upper_limit>
    <param name="pos_kp">10</param>
    <param name="pos_ki">1</param>
    <param name="pos_kd">2</param>
    <param name="pos_max_integral_error">10000</param>
    <param name="vel_kp">10</param>
    <param name="vel_ki">5</param>
    <param name="vel_kd">2</param>
    <param name="vel_max_integral_error">10000</param>
    </safety>
  </joint>

  <link name="backLeft_ankle">
    <inertial><mass value="0.158"/><origin xyz="0 0 0"/>
    <inertia ixx="0.00016" iyy="0.00016" izz="0.00016" ixy="0" ixz="0" iyz="0"/></inertial>
    <visual   ><geometry><cylinder radius="0.015" length="0.05"/></geometry></visual>
     <collision><geometry><cylinder radius="0.015" length="0.05"/></geometry>
    <surface><friction><ode><mu>1.0</mu><mu2>1.0</mu2></ode>
    </friction><contact><ode><kp>10</kp><kd>50</kd></ode></contact></surface>
    </collision>
  </link>
  <joint name="backLeft_ankle_joint" type="revolute">
    <parent link="backLeft_connector"/>
    <child  link="backLeft_ankle"/>
    <origin xyz="0.08 0 0" rpy="0.1 0 0.8"/>
    <axis xyz="0 0 1"/>
    <limit lower="-3.14" upper="3.14" effort="50.88" velocity="1"/>
    <dynamics damping="0.05" friction="2.5"/>
    <safety>
    <soft_lower_limit>-3.0</soft_lower_limit>
    <soft_upper_limit> 3.0</soft_upper_limit>
    <k_position> 50.0 </k_position>
    <k_velocity> 10.0  </k_velocity>
    </safety>
  </joint>

  <link name="backLeft_foot">
    <inertial><mass value="0.03"/><origin xyz="0 0 0"/>
      <inertia ixx="2e-5" iyy="2e-5" izz="2e-5" ixy="0" ixz="0" iyz="0"/></inertial>
    <visual>
    <origin xyz="0 0 0" rpy="0 0 0"/>
    <geometry>
      <mesh
        filename="/home/edipo/ros2_orange/src/quadruped_arm_motion/meshes/foot_3.stl"
        scale="1 1 1"/>
    </geometry>
    </visual>
    <collision>
    <origin xyz="0 0 0" rpy="0 0 0"/>
    <geometry>
      <mesh
        filename="/home/edipo/ros2_orange/src/quadruped_arm_motion/meshes/foot_3.stl"
        scale="1 1 1"/>
    </geometry>
    <surface>
      <friction>
        <ode>
          <mu>1.0</mu>
          <mu2>1.0</mu2>
        </ode>
      </friction>
      <contact>
        <ode>
          <kp>10</kp>
          <kd>50</kd>
        </ode>
      </contact>
    </surface>
    </collision>
  </link>
  <joint name="backLeft_foot_joint" type="fixed">
    <parent link="backLeft_ankle"/>
    <child  link="backLeft_foot"/>
    <origin xyz="0.06 0 0"/>
     
    <dynamics damping="0.05" friction="2.5"/>
    <safety>
    <soft_lower_limit>-3.0</soft_lower_limit>
    <soft_upper_limit> 3.0</soft_upper_limit>
    <k_position> 50.0 </k_position>
    <k_velocity> 10.0  </k_velocity>
    </safety>
  </joint>
 
  <link name="backRight_hip_motor">
    <inertial><mass value="0.158"/><origin xyz="0 0 0"/>
      <inertia ixx="0.00016" iyy="0.00016" izz="0.00016" ixy="0" ixz="0" iyz="0"/></inertial>
    <visual>
    <origin xyz="0.035 0.021  -0.06" rpy="0 0 0"/>
    <geometry>
      <mesh
        filename="/home/edipo/ros2_orange/src/quadruped_arm_motion/meshes/servo_7y.stl"
        scale="1 1 1"/>
    </geometry>
    </visual>
    <collision>
      <origin xyz="0.045 0.015  -0.06" rpy="0 0 0"/>
      <geometry>
        <mesh
          filename="/home/edipo/ros2_orange/src/quadruped_arm_motion/meshes/servo_7y.stl"
          scale="1 1 1"/>
      </geometry>
      <surface>
        <friction>
          <ode>
            <mu>1.0</mu>
            <mu2>1.0</mu2>
          </ode>
        </friction>
        <contact>
          <ode>
            <kp>10</kp>
            <kd>50</kd>
          </ode>
        </contact>
      </surface>
    </collision>
  </link>
  <joint name="backRight_hip_motor_joint" type="revolute">
    <parent link="base_link"/>
    <child  link="backRight_hip_motor"/>
    <origin xyz="-0.275 -0.085 0.03" rpy="0 1.5708 0"/>
    <axis xyz="0 0 1"/>
    <limit lower="-3.14" upper="3.14" effort="50.88" velocity="1"/>
    <dynamics damping="0.05" friction="2.5"/>
    <safety>
    <soft_lower_limit>-3.0</soft_lower_limit>
    <soft_upper_limit> 3.0</soft_upper_limit>
    <k_position> 50.0 </k_position>
    <k_velocity> 10.0  </k_velocity>
    </safety>
  </joint>
  
  <link name="backRight_knee">
    <inertial><mass value="0.158"/><origin xyz="0.1 0.1 0"/>
      <inertia ixx="0.00016" iyy="0.00016" izz="0.00016" ixy="0" ixz="0" iyz="0"/></inertial>
    <visual   ><geometry><cylinder radius="0.015" length="0.05"/></geometry></visual>
    <collision><geometry><cylinder radius="0.015" length="0.05"/></geometry>
    <surface><friction><ode><mu>1.0</mu><mu2>1.0</mu2></ode>
    </friction><contact><ode><kp>10</kp><kd>50</kd></ode></contact></surface>
    </collision>
  </link>
  <joint name="backRight_knee_joint" type="revolute">
    <parent link="backRight_hip_motor"/>
    <child  link="backRight_knee"/>
    <origin xyz="0.035 -0.055 0.025" rpy="1.5708 0.5 0"/>
    <axis xyz="0 0 1"/>
    <limit lower="-1.57" upper="1.57" effort="50.88" velocity="1"/>
    <dynamics damping="0.05" friction="2.5"/>
    <safety>
    <soft_lower_limit>-3.0</soft_lower_limit>
    <soft_upper_limit> 3.0</soft_upper_limit>
    <k_position> 50.0 </k_position>
    <k_velocity> 10.0  </k_velocity>
  </safety>
  </joint>

  <link name="backRight_connector">
    <inertial><mass value="0.05"/><origin xyz="0 0 0"/>
      <inertia ixx="0.00016" iyy="0.00016" izz="0.00016" ixy="0" ixz="0" iyz="0"/></inertial>
    <visual   ><geometry><box size="0.125 0.04 0.02" /></geometry></visual>
    <collision><geometry><box size="0.125 0.04 0.02" /></geometry>
    <surface><friction><ode><mu>1.0</mu><mu2>1.0</mu2></ode></friction><contact><ode><kp>10</kp><kd>50</kd></ode></contact></surface>
    </collision>
  </link>
  <joint name="backRight_connectorJoin" type="fixed">
    <parent link="backRight_knee"/>
    <child  link="backRight_connector"/>
    <origin xyz="0.08 0 0" rpy="0 0 0" />
    <axis xyz="0 0 1"/>
    <dynamics damping="0.05" friction="2.5"/>
    <safety>
    <soft_lower_limit>-3.0</soft_lower_limit>
    <soft_upper_limit> 3.0</soft_upper_limit>
    <param name="pos_kp">10</param>
    <param name="pos_ki">1</param>
    <param name="pos_kd">2</param>
    <param name="pos_max_integral_error">10000</param>
    <param name="vel_kp">10</param>
    <param name="vel_ki">5</param>
    <param name="vel_kd">2</param>
    <param name="vel_max_integral_error">10000</param>
    </safety>
  </joint>

  <link name="backRight_ankle">
    <inertial><mass value="0.158"/><origin xyz="0 0 0"/>
    <inertia ixx="0.00016" iyy="0.00016" izz="0.00016" ixy="0" ixz="0" iyz="0"/></inertial>
     <visual   ><geometry><cylinder radius="0.015" length="0.05"/></geometry></visual>
     <collision><geometry><cylinder radius="0.015" length="0.05"/></geometry>
    <surface><friction><ode><mu>1.0</mu><mu2>1.0</mu2></ode>
    </friction><contact><ode><kp>10</kp><kd>50</kd></ode></contact></surface>
    </collision>
  </link>
  <joint name="backRight_ankle_joint" type="revolute">
    <parent link="backRight_connector"/>
    <child  link="backRight_ankle"/>
    <origin xyz="0.08 0 0" rpy="0.1 0 0.8"/>
    <axis xyz="0 0 1"/>
    <limit lower="-3.14" upper="3.14" effort="50.88" velocity="1"/>
    <dynamics damping="0.05" friction="2.5"/>
    <safety>
    <soft_lower_limit>-3.0</soft_lower_limit>
    <soft_upper_limit> 3.0</soft_upper_limit>
    <k_position> 50.0 </k_position>
    <k_velocity> 10.0  </k_velocity>
    </safety>
  </joint>

  <link name="backRight_foot">
    <inertial><mass value="0.03"/><origin xyz="0 0 0" rpy="0 0 0"/>
    <inertia ixx="2e-5" iyy="2e-5" izz="2e-5" ixy="0" ixz="0" iyz="0"/></inertial>
    <visual>
    <origin xyz="0 0 0" rpy="0 0 0"/>
    <geometry>
      <mesh
        filename="/home/edipo/ros2_orange/src/quadruped_arm_motion/meshes/foot_3.stl"
        scale="1 1 1"/>
    </geometry>
    </visual>
    <collision>
      <origin xyz="0 0 0" rpy="0 0 0"/>
      <geometry>
        <mesh
          filename="/home/edipo/ros2_orange/src/quadruped_arm_motion/meshes/foot_3.stl"
          scale="1 1 1"/>
      </geometry>
      <surface>
        <friction>
          <ode>
            <mu>1.0</mu>
            <mu2>1.0</mu2>
          </ode>
        </friction>
        <contact>
          <ode>
            <kp>10</kp>
            <kd>50</kd>
          </ode>
        </contact>
      </surface>
    </collision>
  </link>
  <joint name="backRight_foot_joint" type="fixed">
    <parent link="backRight_ankle"/>
    <child  link="backRight_foot"/>
    <origin xyz="0.06 0 0"/>
    <dynamics damping="0.05" friction="2.5"/>
    <safety>
    <soft_lower_limit>-3.0</soft_lower_limit>
    <soft_upper_limit> 3.0</soft_upper_limit>
    <k_position> 50.0 </k_position>
    <k_velocity> 10.0  </k_velocity>
  </safety>
  </joint>

  <link name="M0_big">
    <inertial><mass value="0.158"/><origin xyz="0 0 0"/>
      <inertia ixx="0.00016" iyy="0.00016" izz="0.00016" ixy="0" ixz="0" iyz="0"/></inertial>
    <visual>
    <origin xyz="0.04 0 -0.02" rpy="0 0 0"/>
    <geometry>
      <mesh
        filename="/home/edipo/ros2_orange/src/quadruped_arm_motion/meshes/M0.stl"
        scale="1 1 1"/>
    </geometry>
    </visual>0
    <collision>
      <origin xyz="0.04 0 -0.02" rpy="0 0 0"/>
      <geometry>
        <mesh
          filename="/home/edipo/ros2_orange/src/quadruped_arm_motion/meshes/M0.stl"
          scale="1 1 1"/>
      </geometry>
      <surface>
        <friction>
          <ode>
            <mu>1.0</mu>
            <mu2>1.0</mu2>
          </ode>
        </friction>
        <contact>
          <ode>
            <kp>10</kp>
            <kd>50</kd>
          </ode>
        </contact>
      </surface>
    </collision>
  </link>
  <joint name="articulacion1" type="revolute">
    <parent link="base_link"/>
    <child  link="M0_big"/>
    <origin xyz="0 -0.03 0.1" rpy="0 0 0"/>
    <axis xyz="0 0 1"/>
    <limit lower="-1.14" upper="1.14" effort="49.03325" velocity="1"/>
    <dynamics damping="0.05" friction="2.5"/>
    <safety>
    <soft_lower_limit>-1.0</soft_lower_limit>
    <soft_upper_limit> 1.0</soft_upper_limit>
    <param name="pos_kp">10</param>
    <param name="pos_ki">1</param>
    <param name="pos_kd">2</param>
    <param name="pos_max_integral_error">10000</param>
    <param name="vel_kp">10</param>
    <param name="vel_ki">5</param>
    <param name="vel_kd">2</param>
    <param name="vel_max_integral_error">10000</param>
    </safety>
  </joint>
  <link name="Motor_square">
    <inertial><mass value="0.08158"/><origin xyz="0 0 0"/>
      <inertia ixx="0.00016" iyy="0.00016" izz="0.00016" ixy="0" ixz="0" iyz="0"/></inertial>
    <visual   ><geometry><box size="0.05 0.05 0.08" /></geometry></visual>
    <collision><geometry><box size="0.05 0.05 0.08" /></geometry>
    <surface><friction><ode><mu>1.0</mu><mu2>1.0</mu2></ode></friction><contact><ode><kp>10</kp><kd>50</kd></ode></contact></surface>
    </collision>
  </link>
  <joint name="Motor_square_Join" type="fixed">
    <parent link="M0_big"/>
    <child  link="Motor_square"/>
    <origin xyz="0.0 0 0.05" rpy="0 0 0" />
    <axis xyz="0 0 0"/>
    <dynamics damping="0.05" friction="2.5"/>
    <safety>
    <soft_lower_limit>-3.0</soft_lower_limit>
    <soft_upper_limit> 3.0</soft_upper_limit>
    <param name="pos_kp">10</param>
    <param name="pos_ki">1</param>
    <param name="pos_kd">2</param>
    <param name="pos_max_integral_error">10000</param>
    <param name="vel_kp">10</param>
    <param name="vel_ki">5</param>
    <param name="vel_kd">2</param>
    <param name="vel_max_integral_error">10000</param>
    </safety>
  </joint> 

  <link name="M1_100">
    <inertial><mass value="0.158"/><origin xyz="0 0 0"/>
      <inertia ixx="0.00016" iyy="0.00016" izz="0.00016" ixy="0" ixz="0" iyz="0"/></inertial>
    <visual   ><geometry><cylinder radius="0.025" length="0.1"/></geometry></visual>
    <collision><geometry><cylinder radius="0.025" length="0.1"/></geometry>
    <surface><friction><ode><mu>1.0</mu><mu2>1.0</mu2></ode></friction><contact><ode><kp>10</kp><kd>50</kd></ode></contact></surface>
    </collision>
  </link>
  <joint name="articulacion2" type="revolute">
    <parent link="Motor_square"/>
    <child  link="M1_100"/>
    <origin xyz="0.0 0 0.05" rpy="-1.5708 0.0 0" />
    <axis xyz="0 0 1"/>
   <limit lower="-1.14" upper="1.14" effort="49.03325" velocity="1"/>
    <dynamics damping="0.05" friction="2.5"/>
    <safety>
    <soft_lower_limit>-1.0</soft_lower_limit>
    <soft_upper_limit> 1.0</soft_upper_limit>
    <param name="pos_kp">10</param>
    <param name="pos_ki">1</param>
    <param name="pos_kd">2</param>
    <param name="pos_max_integral_error">10000</param>
    <param name="vel_kp">10</param>
    <param name="vel_ki">5</param>
    <param name="vel_kd">2</param>
    <param name="vel_max_integral_error">10000</param>
    </safety>
  </joint>
  <link name="Connector_1">
    <inertial><mass value="0.05"/><origin xyz="0 0 0"/>
      <inertia ixx="0.00016" iyy="0.00016" izz="0.00016" ixy="0" ixz="0" iyz="0"/></inertial>
    <visual>
    <origin xyz="0.0 0 0" rpy="0 1.578 0"/>
    <geometry>
      <mesh
        filename="/home/edipo/ros2_orange/src/quadruped_arm_motion/meshes/arm_200.stl"
        scale="1 1 1"/>
    </geometry>
    </visual>
    <collision>
      <origin xyz="0.0 0 0" rpy="0 1.578 0"/>
      <geometry>
        <mesh
          filename="/home/edipo/ros2_orange/src/quadruped_arm_motion/meshes/arm_200.stl"
          scale="1 1 1"/>
      </geometry>
      <surface>
        <friction>
          <ode>
            <mu>1.0</mu>
            <mu2>1.0</mu2>
          </ode>
        </friction>
        <contact>
          <ode>
            <kp>10</kp>
            <kd>50</kd>
          </ode>
        </contact>
      </surface>
    </collision>
  </link>
  <joint name="Connector_1_join" type="fixed">
    <parent link="M1_100"/>
    <child  link="Connector_1"/>
    <origin xyz="0.0 0 0" rpy="0 0 0" />
    <axis xyz="0 0 1"/>
    <dynamics damping="0.05" friction="2.5"/>
    <safety>
    <soft_lower_limit>-3.0</soft_lower_limit>
    <soft_upper_limit> 3.0</soft_upper_limit>
    <param name="pos_kp">10</param>
    <param name="pos_ki">1</param>
    <param name="pos_kd">2</param>
    <param name="pos_max_integral_error">10000</param>
    <param name="vel_kp">10</param>
    <param name="vel_ki">5</param>
    <param name="vel_kd">2</param>
    <param name="vel_max_integral_error">10000</param>
    </safety>
  </joint>
  <link name="M2_100">
    <inertial><mass value="0.08158"/><origin xyz="0 0 0"/>
      <inertia ixx="0.00016" iyy="0.00016" izz="0.00016" ixy="0" ixz="0" iyz="0"/></inertial>
    <visual   ><geometry><cylinder radius="0.025" length="0.1"/></geometry></visual>
    <collision><geometry><cylinder radius="0.025" length="0.1"/></geometry>
    <surface><friction><ode><mu>1.0</mu><mu2>1.0</mu2></ode></friction><contact><ode><kp>10</kp><kd>50</kd></ode></contact></surface>
    </collision>
  </link>
  <joint name="articulacion3" type="revolute">
    <parent link="Connector_1"/>
    <child  link="M2_100"/>
    <origin xyz="0.0 -0.25  0  " rpy="0 0 0.5" />
    <axis xyz="0 0 1"/>
    <limit lower="-1.14" upper="1.14" effort="49.03325" velocity="1"/>
    <dynamics damping="0.05" friction="2.5"/>
    <safety>
    <soft_lower_limit>-1.0</soft_lower_limit>
    <soft_upper_limit> 1.0</soft_upper_limit>
    <param name="pos_kp">10</param>
    <param name="pos_ki">1</param>
    <param name="pos_kd">2</param>
    <param name="pos_max_integral_error">10000</param>
    <param name="vel_kp">10</param>
    <param name="vel_ki">5</param>
    <param name="vel_kd">2</param>
    <param name="vel_max_integral_error">10000</param>
  </safety>
  </joint>
  <link name="Motor_square_2">
    <inertial><mass value="0.08158"/><origin xyz="0 0 0"/>
      <inertia ixx="0.00016" iyy="0.00016" izz="0.00016" ixy="0" ixz="0" iyz="0"/></inertial>
    <visual   ><geometry><box size="0.05 0.1 0.05" /></geometry></visual>
    <collision><geometry><box size="0.05 0.1 0.05" /></geometry>
    <surface><friction><ode><mu>1.0</mu><mu2>1.0</mu2></ode></friction><contact><ode><kp>10</kp><kd>50</kd></ode></contact></surface>
    </collision>
  </link>
  <joint name="Motor_square_2_Join" type="fixed">
    <parent link="M2_100"/>
    <child  link="Motor_square_2"/>
    <origin xyz="0.0 -0.05 0" rpy="0 0 0" />
    <axis xyz="0 0 0"/>
    <dynamics damping="0.05" friction="2.5"/>
    <safety>
    <soft_lower_limit>-3.0</soft_lower_limit>
    <soft_upper_limit> 3.0</soft_upper_limit>
    <param name="pos_kp">10</param>
    <param name="pos_ki">1</param>
    <param name="pos_kd">2</param>
    <param name="pos_max_integral_error">10000</param>
    <param name="vel_kp">10</param>
    <param name="vel_ki">5</param>
    <param name="vel_kd">2</param>
    <param name="vel_max_integral_error">10000</param>
    </safety>
  </joint> 
  <link name="M3_50">
    <inertial><mass value="0.08158"/><origin xyz="0 0 0"/>
    <inertia ixx="0.00016" iyy="0.00016" izz="0.00016" ixy="0" ixz="0" iyz="0"/></inertial>
    <visual   ><geometry><cylinder radius="0.025" length="0.1"/></geometry></visual>
    <collision><geometry><cylinder radius="0.025" length="0.1"/></geometry>
    <surface><friction><ode><mu>1.0</mu><mu2>1.0</mu2></ode></friction><contact><ode><kp>10</kp><kd>50</kd></ode></contact></surface>
    </collision>
  </link>
  <joint name="articulacion4" type="revolute">
    <parent link="Motor_square_2"/>
    <child  link="M3_50"/>
    <origin xyz="0 -0.07 0" rpy=" 0 1.5708 0" />
    <axis xyz="0 0 1"/>
    <limit lower="-1.14" upper="1.14" effort="49.03325" velocity="1"/>
    <dynamics damping="0.05" friction="2.5"/>
    <safety>
      <soft_lower_limit>-1.0</soft_lower_limit>
      <soft_upper_limit> 1.0</soft_upper_limit>
      <param name="pos_kp">10</param>
      <param name="pos_ki">1</param>
      <param name="pos_kd">2</param>
      <param name="pos_max_integral_error">10000</param>
      <param name="vel_kp">10</param>
      <param name="vel_ki">5</param>
      <param name="vel_kd">2</param>
      <param name="vel_max_integral_error">10000</param>
    </safety>
  </joint>
  <link name="Connector_2">
    <inertial><mass value="0.05"/><origin xyz="0 0 0"/>
      <inertia ixx="0.00016" iyy="0.00016" izz="0.00016" ixy="0" ixz="0" iyz="0"/></inertial>
    <visual>
    <origin xyz="0.0 0 0" rpy="-1.578 0 0"/>
    <geometry>
      <mesh
        filename="/home/edipo/ros2_orange/src/quadruped_arm_motion/meshes/arm_200.stl"
        scale="1 1 1"/>
    </geometry>
    </visual>
    <collision>
      <origin xyz="0.0 0 0" rpy="-1.578 0 0"/>
      <geometry>
        <mesh
          filename="/home/edipo/ros2_orange/src/quadruped_arm_motion/meshes/arm_200.stl"
          scale="1 1 1"/>
      </geometry>
      <surface>
        <friction>
          <ode>
            <mu>1.0</mu>
            <mu2>1.0</mu2>
          </ode>
        </friction>
        <contact>
          <ode>
            <kp>10</kp>
            <kd>50</kd>
          </ode>
        </contact>
      </surface>
    </collision>
  </link>
  <joint name="Connector_2_join" type="fixed">
    <parent link="M3_50"/>
    <child  link="Connector_2"/>
    <origin xyz="0.0 0 0" rpy="0 0 0" />
    <axis xyz="0 0 1"/>
    <dynamics damping="0.05" friction="2.5"/>
    <safety>
    <soft_lower_limit>-3.0</soft_lower_limit>
    <soft_upper_limit> 3.0</soft_upper_limit>
    <param name="pos_kp">10</param>
    <param name="pos_ki">1</param>
    <param name="pos_kd">2</param>
    <param name="pos_max_integral_error">10000</param>
    <param name="vel_kp">10</param>
    <param name="vel_ki">5</param>
    <param name="vel_kd">2</param>
    <param name="vel_max_integral_error">10000</param>
    </safety>
  </joint>
  <link name="Motor_square_3">
    <inertial><mass value="0.05"/><origin xyz="0 0 0"/>
      <inertia ixx="0.00016" iyy="0.00016" izz="0.00016" ixy="0" ixz="0" iyz="0"/></inertial>
    <visual   ><geometry><box size=" 0.05  0.05 0.1" /></geometry></visual>
    <collision><geometry><box size="0.05 0.05 0.1" /></geometry>
    <surface><friction><ode><mu>1.0</mu><mu2>1.0</mu2></ode></friction><contact><ode><kp>10</kp><kd>50</kd></ode></contact></surface>
    </collision>
  </link>
  <joint name="Motor_square_3_Join" type="fixed">
    <parent link="Connector_2"/>
    <child  link="Motor_square_3"/>
    <origin xyz="0 0 0.25" rpy="0 0 0" />
    <axis xyz="0 0 0"/>
    <dynamics damping="0.05" friction="2.5"/>
    <safety>
    <soft_lower_limit>-3.0</soft_lower_limit>
    <soft_upper_limit> 3.0</soft_upper_limit>
    <param name="pos_kp">10</param>
    <param name="pos_ki">1</param>
    <param name="pos_kd">2</param>
    <param name="pos_max_integral_error">10000</param>
    <param name="vel_kp">10</param>
    <param name="vel_ki">5</param>
    <param name="vel_kd">2</param>
    <param name="vel_max_integral_error">10000</param>
    </safety>
  </joint> 
  <link name="M4_50">
    <inertial><mass value="0.08158"/><origin xyz="0 0 0"/>
      <inertia ixx="0.00016" iyy="0.00016" izz="0.00016" ixy="0" ixz="0" iyz="0"/></inertial>
    <visual   ><geometry><cylinder radius="0.025" length="0.1"/></geometry></visual>
    <collision><geometry><cylinder radius="0.025" length="0.1"/></geometry>
    <surface><friction><ode><mu>1.0</mu><mu2>1.0</mu2></ode></friction><contact><ode><kp>10</kp><kd>50</kd></ode></contact></surface>
    </collision>
  </link>
  <joint name="articulacion5" type="revolute">
    <parent link="Motor_square_3"/>
    <child  link="M4_50"/>
    <origin xyz="0 0 0.05" rpy="-1.5708 0 0" />
    <axis xyz="0 0 1"/>
    <limit lower="-1.14" upper="1.14" effort="49.03325" velocity="1"/>
    <dynamics damping="0.05" friction="2.5"/>
    <safety>
    <soft_lower_limit>-1.0</soft_lower_limit>
    <soft_upper_limit> 1.0</soft_upper_limit>
    <param name="pos_kp">10</param>
    <param name="pos_ki">1</param>
    <param name="pos_kd">2</param>
    <param name="pos_max_integral_error">10000</param>
    <param name="vel_kp">10</param>
    <param name="vel_ki">5</param>
    <param name="vel_kd">2</param>
    <param name="vel_max_integral_error">10000</param>
    </safety>
  </joint>

  <link name="endEfector">
    <inertial><mass value="0.08158"/><origin xyz="0 0 0"/>
      <inertia ixx="0.00016" iyy="0.00016" izz="0.00016" ixy="0" ixz="0" iyz="0"/></inertial>
    <visual   ><geometry><box size=" 0.05  0.05 0.05" /></geometry></visual>
    <collision><geometry><box size="0.05 0.05 0.05" /></geometry>
    <surface><friction><ode><mu>1.0</mu><mu2>1.0</mu2></ode></friction><contact><ode><kp>10</kp><kd>50</kd></ode></contact></surface>
    </collision>
  </link>
  <joint name="endEfectorJoin" type="fixed">
    <parent link="Motor_square_3"/>
    <child  link="endEfector"/>
    <origin xyz="0 0 0.1" rpy="0 0 0" />
    <axis xyz="0 0 1"/>
    <dynamics damping="0.05" friction="2.5"/>
    <safety>
    <soft_lower_limit>-3.0</soft_lower_limit>
    <soft_upper_limit> 3.0</soft_upper_limit>
    <param name="pos_kp">10</param>
    <param name="pos_ki">1</param>
    <param name="pos_kd">2</param>
    <param name="pos_max_integral_error">10000</param>
    <param name="vel_kp">10</param>
    <param name="vel_ki">5</param>
    <param name="vel_kd">2</param>
    <param name="vel_max_integral_error">10000</param>
    </safety>
  </joint>

  <!-- Plugin para Gazebo ROS 2 Control -->
  
  <!-- Bloque ros2_control -->
  <ros2_control name="QuadrupedArmHardware" type="system">
    <hardware>
      <plugin>gazebo_ros2_control/GazeboSystem</plugin>
    </hardware>

    <!-- Interfaces de todas las articulaciones (piernas + brazo) -->
    <joint name="frontLeft_hip_motor_joint">
      <command_interface name="effort"/>
      <command_interface name="position"/>
      <state_interface name="position"/>
      <state_interface name="velocity"/>
      <state_interface name="effort"/>  
    </joint>
    <joint name="frontLeft_knee_joint">
      <command_interface name="effort"/>
      <command_interface name="position"/>
      <state_interface name="position"/>
      <state_interface name="velocity"/>
      <state_interface name="effort"/>  
    </joint>
    <joint name="frontLeft_ankle_joint">
      <command_interface name="effort"/>
      <command_interface name="position"/>
      <state_interface name="position"/>
      <state_interface name="velocity"/>
      <state_interface name="effort"/>  
    </joint>
    <joint name="frontRight_hip_motor_joint">
      <command_interface name="effort"/>
      <command_interface name="position"/>
      <state_interface name="position"/>
      <state_interface name="velocity"/>
      <state_interface name="effort"/>  
    </joint>
    <joint name="frontRight_knee_joint">
      <command_interface name="effort"/>
      <command_interface name="position"/>
      <state_interface name="position"/>
      <state_interface name="velocity"/>
      <state_interface name="effort"/>  
    </joint>
    <joint name="frontRight_ankle_joint">
      <command_interface name="effort"/>
      <command_interface name="position"/>
      <state_interface name="position"/>
      <state_interface name="velocity"/>
      <state_interface name="effort"/>  
    </joint>
    <joint name="backLeft_hip_motor_joint">
      <command_interface name="effort"/>
      <command_interface name="position"/>
      <state_interface name="position"/>
      <state_interface name="velocity"/>
      <state_interface name="effort"/>  
    </joint>
    <joint name="backLeft_knee_joint">
      <command_interface name="effort"/>
      <command_interface name="position"/>
      <state_interface name="position"/>
      <state_interface name="velocity"/>
      <state_interface name="effort"/>  
    </joint>
    <joint name="backLeft_ankle_joint">
      <command_interface name="effort"/>
      <command_interface name="position"/>
      <state_interface name="position"/>
      <state_interface name="velocity"/>
      <state_interface name="effort"/>  
    </joint>
    <joint name="backRight_hip_motor_joint">
      <command_interface name="effort"/>
      <command_interface name="position"/>
      <state_interface name="position"/>
      <state_interface name="velocity"/>
      <state_interface name="effort"/>  
    </joint>
    <joint name="backRight_knee_joint">
      <command_interface name="effort"/>
      <command_interface name="position"/>
      <state_interface name="position"/>
      <state_interface name="velocity"/>
      <state_interface name="effort"/>  
    </joint>
    <joint name="backRight_ankle_joint">
      <command_interface name="effort"/>
      <command_interface name="position"/>
      <state_interface name="position"/>
      <state_interface name="velocity"/>
      <state_interface name="effort"/>  
    </joint>
    <joint name="articulacion1">
    
      <command_interface name="effort"/>
      <command_interface name="position"/>
      <state_interface name="position"/>
      <state_interface name="velocity"/>
      <state_interface name="effort"/>  
    </joint>
    <joint name="articulacion2">
      <command_interface name="effort"/>
      <command_interface name="position"/>
      <state_interface name="position"/>
      <state_interface name="velocity"/>
      <state_interface name="effort"/>  
    </joint>
    <joint name="articulacion3">
      <command_interface name="effort"/>
      <command_interface name="position"/>
      <state_interface name="position"/>
      <state_interface name="velocity"/>
      <state_interface name="effort"/>  
    </joint>
    <joint name="articulacion4">
      <command_interface name="effort"/>
      <command_interface name="position"/>
      <state_interface name="position"/>
      <state_interface name="velocity"/>
      <state_interface name="effort"/>  
    </joint>
    <joint name="articulacion5">
      <command_interface name="effort"/>
      <command_interface name="position"/>
      <state_interface name="position"/>
      <state_interface name="velocity"/>
      <state_interface name="effort"/>  
    </joint>
  </ros2_control>
<!-- Pierna frontal izquierda -->
  <transmission name="frontLeft_hip_trans">
    <type>transmission_interface/SimpleTransmission</type>
    <joint name="frontLeft_hip_motor_joint">
      <hardwareInterface>hardware_interface/EffortJointInterface</hardwareInterface>
      <hardwareInterface>hardware_interface/PositionJointInterface</hardwareInterface>
    </joint>
    <actuator name="frontLeft_hip_motor_actuator">
      <mechanicalReduction>1</mechanicalReduction>
    </actuator>
  </transmission>
  <transmission name="frontLeft_knee_trans">
    <type>transmission_interface/SimpleTransmission</type>
    <joint name="frontLeft_knee_joint">
      <hardwareInterface>hardware_interface/EffortJointInterface</hardwareInterface>
      <hardwareInterface>hardware_interface/PositionJointInterface</hardwareInterface>
    </joint>
    <actuator name="frontLeft_knee_actuator">
      <mechanicalReduction>1</mechanicalReduction>
    </actuator>
  </transmission>
  <transmission name="frontLeft_ankle_trans">
    <type>transmission_interface/SimpleTransmission</type>
    <joint name="frontLeft_ankle_joint">
      <hardwareInterface>hardware_interface/EffortJointInterface</hardwareInterface>
      <hardwareInterface>hardware_interface/PositionJointInterface</hardwareInterface>
    </joint>
    <actuator name="frontLeft_ankle_actuator">
      <mechanicalReduction>1</mechanicalReduction>
    </actuator>
  </transmission>

  <!-- Pierna frontal derecha -->
  <transmission name="frontRight_hip_trans">
    <type>transmission_interface/SimpleTransmission</type>
    <joint name="frontRight_hip_motor_joint">
      <hardwareInterface>hardware_interface/EffortJointInterface</hardwareInterface>
      <hardwareInterface>hardware_interface/PositionJointInterface</hardwareInterface>
    </joint>
    <actuator name="frontRight_hip_motor_actuator">
      <mechanicalReduction>1</mechanicalReduction>
    </actuator>
  </transmission>
  <transmission name="frontRight_knee_trans">
    <type>transmission_interface/SimpleTransmission</type>
    <joint name="frontRight_knee_joint">
      <hardwareInterface>hardware_interface/EffortJointInterface</hardwareInterface>
      <hardwareInterface>hardware_interface/PositionJointInterface</hardwareInterface>
    </joint>
    <actuator name="frontRight_knee_actuator">
      <mechanicalReduction>1</mechanicalReduction>
    </actuator>
  </transmission>
  <transmission name="frontRight_ankle_trans">
    <type>transmission_interface/SimpleTransmission</type>
    <joint name="frontRight_ankle_joint">
      <hardwareInterface>hardware_interface/EffortJointInterface</hardwareInterface>
      <hardwareInterface>hardware_interface/PositionJointInterface</hardwareInterface>
    </joint>
    <actuator name="frontRight_ankle_actuator">
      <mechanicalReduction>1</mechanicalReduction>
    </actuator>
  </transmission>

  <!-- Pierna trasera izquierda -->
  <transmission name="backLeft_hip_trans">
    <type>transmission_interface/SimpleTransmission</type>
    <joint name="backLeft_hip_motor_joint">
      <hardwareInterface>hardware_interface/EffortJointInterface</hardwareInterface>
      <hardwareInterface>hardware_interface/PositionJointInterface</hardwareInterface>
    </joint>
    <actuator name="backLeft_hip_motor_actuator">
      <mechanicalReduction>1</mechanicalReduction>
    </actuator>
  </transmission>
  <transmission name="backLeft_knee_trans">
    <type>transmission_interface/SimpleTransmission</type>
    <joint name="backLeft_knee_joint">
      <hardwareInterface>hardware_interface/EffortJointInterface</hardwareInterface>
      <hardwareInterface>hardware_interface/PositionJointInterface</hardwareInterface>
    </joint>
    <actuator name="backLeft_knee_actuator">
      <mechanicalReduction>1</mechanicalReduction>
    </actuator>
  </transmission>
  <transmission name="backLeft_ankle_trans">
    <type>transmission_interface/SimpleTransmission</type>
    <joint name="backLeft_ankle_joint">
      <hardwareInterface>hardware_interface/EffortJointInterface</hardwareInterface>
      <hardwareInterface>hardware_interface/PositionJointInterface</hardwareInterface>
    </joint>
    <actuator name="backLeft_ankle_actuator">
      <mechanicalReduction>1</mechanicalReduction>
    </actuator>
  </transmission>

  <!-- Pierna trasera derecha -->
  <transmission name="backRight_hip_trans">
    <type>transmission_interface/SimpleTransmission</type>
    <joint name="backRight_hip_motor_joint">
      <hardwareInterface>hardware_interface/EffortJointInterface</hardwareInterface>
      <hardwareInterface>hardware_interface/PositionJointInterface</hardwareInterface>
    </joint>
    <actuator name="backRight_hip_motor_actuator">
      <mechanicalReduction>1</mechanicalReduction>
    </actuator>
  </transmission>
  <transmission name="backRight_knee_trans">
    <type>transmission_interface/SimpleTransmission</type>
    <joint name="backRight_knee_joint">
      <hardwareInterface>hardware_interface/EffortJointInterface</hardwareInterface>
      <hardwareInterface>hardware_interface/PositionJointInterface</hardwareInterface>
    </joint>
    <actuator name="backRight_knee_actuator">
      <mechanicalReduction>1</mechanicalReduction>
    </actuator>
  </transmission>
  <transmission name="backRight_ankle_trans">
    <type>transmission_interface/SimpleTransmission</type>
    <joint name="backRight_ankle_joint">
      <hardwareInterface>hardware_interface/EffortJointInterface</hardwareInterface>
      <hardwareInterface>hardware_interface/PositionJointInterface</hardwareInterface>
    </joint>
    <actuator name="backRight_ankle_actuator">
      <mechanicalReduction>1</mechanicalReduction>
    </actuator>
  </transmission>

  <!-- Brazo -->
  <transmission name="arm_joint1_trans">
    <type>transmission_interface/SimpleTransmission</type>
    <joint name="articulacion1">
      <hardwareInterface>hardware_interface/EffortJointInterface</hardwareInterface>
      <hardwareInterface>hardware_interface/PositionJointInterface</hardwareInterface>
    </joint>
    <actuator name="arm_joint1_actuator">
      <mechanicalReduction>1</mechanicalReduction>
    </actuator>
  </transmission>
  <transmission name="arm_joint2_trans">
    <type>transmission_interface/SimpleTransmission</type>
    <joint name="articulacion2">
      <hardwareInterface>hardware_interface/EffortJointInterface</hardwareInterface>
      <hardwareInterface>hardware_interface/PositionJointInterface</hardwareInterface>
    </joint>
    <actuator name="arm_joint2_actuator">
      <mechanicalReduction>1</mechanicalReduction>
    </actuator>
  </transmission>
  <transmission name="arm_joint3_trans">
    <type>transmission_interface/SimpleTransmission</type>
    <joint name="articulacion3">
      <hardwareInterface>hardware_interface/EffortJointInterface</hardwareInterface>
      <hardwareInterface>hardware_interface/PositionJointInterface</hardwareInterface>
    </joint>
    <actuator name="arm_joint3_actuator">
      <mechanicalReduction>1</mechanicalReduction>
    </actuator>
  </transmission>
  <transmission name="arm_joint4_trans">
    <type>transmission_interface/SimpleTransmission</type>
    <joint name="articulacion4">
      <hardwareInterface>hardware_interface/EffortJointInterface</hardwareInterface>
      <hardwareInterface>hardware_interface/PositionJointInterface</hardwareInterface>
    </joint>
    <actuator name="arm_joint4_actuator">
      <mechanicalReduction>1</mechanicalReduction>
    </actuator>
  </transmission>
  <transmission name="arm_joint5_trans">
    <type>transmission_interface/SimpleTransmission</type>
    <joint name="articulacion5">
      <hardwareInterface>hardware_interface/EffortJointInterface</hardwareInterface>
      <hardwareInterface>hardware_interface/PositionJointInterface</hardwareInterface>
    </joint>
    <actuator name="arm_joint5_actuator">
      <mechanicalReduction>1</mechanicalReduction>
    </actuator>
  </transmission>
  <gazebo>
    <plugin filename="libgazebo_ros2_control.so" name="gazebo_ros2_control">
      <robot_sim_type>gazebo_ros2_control/GazeboSystem</robot_sim_type>
      <hold_joints>true</hold_joints>
      <parameters>/home/edipo/ros2_orange/src/quadruped_arm_motion/config/controllers.yaml</parameters>
    </plugin>
     <physics type="ode">
    <max_contacts>20</max_contacts>
    <contact_surface_layer>0.001</contact_surface_layer>
    <contact_max_correcting_vel>2.0</contact_max_correcting_vel>
  </physics>
  </gazebo>

  <gazebo reference="frontLeft_foot">
    <sensor name="frontLeft_contact" type="contact">
      <!-- Siempre activo -->
      <always_on>1</always_on>
      <!-- Frecuencia de muestreo -->
      <update_rate>100</update_rate>
      <!-- No dibujar la caja en Gazebo/OGRE -->
      <visualize>false</visualize>
      <!-- Indica con qu colisin detecta el contacto -->
      <contact>
        <collision>r_foot_collision</collision>
        <topic>/r_foot_contact</topic>
      </contact>
    </sensor>
  </gazebo>
  
</robot>